Workbook

Sheet Resolved_megares_update_genes_0
A1: Gene_Accession | B1: ED_confirmation | C1: Notes | D1: ED_SNP | E1: Group | F1: Length | G1: Similarity | H1: Source_Database | I1: Type | J1: Class | K1: Mechanism | L1: Group | M1: SNP | N1: Annotation_Status | O1: Mismatch_Groups | P1: Cluster_ID | Q1: Inheritted_matches? | R1: New_Group
A2: BAC0568|actP|sp|Q9X5V3|ATCU_RHILV | B2: done | E2: ACTP | F2: 841 | G2: 100 | H2: BacMet | I2: Multi-compound | J2: Biocide and metal resistance | K2: Biocide and metal resistance protein | L2: ACTP | N2: Needs new annotations | P2: 1722 | Q2: No | R2: No
A3: BAC0040|baeS|sp|P30847|BAES_ECOLI | B3: done | E3: BAES | F3: 467 | G3: 100 | H3: BacMet | I3: Multi-compound | J3: Drug and biocide and metal resistance | K3: Drug and biocide and metal RND efflux regulator | L3: BAES | N3: Needs new annotations | P3: 2675 | Q3: No | R3: No
A4: BAC0597|baeS|tr|D0ZNE2|D0ZNE2_SALT1 | B4: done | E4: BAES | F4: 467 | G4: 100 | H4: BacMet | I4: Multi-compound | J4: Drug and biocide and metal resistance | K4: Drug and biocide and metal RND efflux regulator | L4: BAES | N4: Needs new annotations | P4: 2676 | Q4: No | R4: No
A5: BAC0054|bmrR|sp|P39075|BMRR_BACSU | B5: done | E5: BMRR | F5: 278 | G5: 100 | H5: BacMet | I5: Multi-compound | J5: Drug and biocide resistance | K5: Multidrug-efflux transporter regulator | L5: BMRR | N5: Needs new annotations | P5: 3184 | Q5: No | R5: No
A6: BAC0361|chrI|tr|Q1L9W3|Q1L9W3_RALME | B6: done | E6: CHRI | F6: 164 | G6: 100 | H6: BacMet | I6: Metals | J6: Chromium resistance | K6: Chromium resistance regulator | L6: CHRI | N6: Needs new annotations | P6: 3368 | Q6: No | R6: No
A7: BAC0501|emrCsm|tr|B2FIC8|B2FIC8_STRMK | B7: done | E7: EMRCSM | F7: 497 | G7: 100 | H7: BacMet | I7: Multi-compound | J7: Drug and biocide resistance | K7: Drug and biocide MFS efflux pumps | L7: EMRCSM | N7: Needs new annotations | P7: 2586 | Q7: No | R7: No
A8: BAC0158|fabL/ygaA|sp|P71079|FABL_BACSU | B8: done | E8: FABL | F8: 250 | G8: 100 | H8: BacMet | I8: Biocides | J8: Phenolic compound resistance | K8: Phenolic resistance protein | L8: FABL | N8: Needs new annotations | P8: 3226 | Q8: No | R8: No
A9: BAC0216|mdtI/ydgE|sp|P69210|MDTI_ECOLI | B9: done | E9: MDTI | F9: 109 | G9: 100 | H9: BacMet | I9: Multi-compound | J9: Drug and biocide resistance | K9: Drug and biocide SMR efflux pumps | L9: MDTI | N9: Needs new annotations | P9: 3505 | Q9: No | R9: No
A10: BAC0758|abuO|tr|B0VDE7|B0VDE7_ACIBY | B10: done | E10: ABUO | F10: 448 | G10: 100 | H10: BacMet | I10: Biocides | J10: Multi-biocide resistance | K10: Multi-biocide RND efflux pump | L10: ABUO | N10: Inherited without clustering | P10: 2732 | Q10: No | R10: No
A11: BAC0038|asr|sp|P36560|ASR_ECOLI | B11: done | E11: ASR | F11: 102 | G11: 100 | H11: BacMet | I11: Biocides | J11: Acid resistance | K11: Acid resistance protein | L11: ASR | N11: Inherited without clustering | P11: 3524 | Q11: No | R11: No
A12: BAC0051|bltD|sp|P39909|BLTD_BACSU | B12: done | E12: BLTD | F12: 152 | G12: 100 | H12: BacMet | I12: Biocides | J12: Polyamine resistance | K12: Spermine/spermidine acetyltransferase | L12: BLTD | N12: Inherited without clustering | P12: 3382 | Q12: No | R12: No
A13: BAC0052|bltR|sp|P39842|BLTR_BACSU | B13: done | E13: BLTR | F13: 273 | G13: 100 | H13: BacMet | I13: Biocides | J13: Multi-biocide resistance | K13: Multi-biocide resistance regulator | L13: BLTR | N13: Inherited without clustering | P13: 3194 | Q13: No | R13: No
... A750: BAC0466|zraP|sp|Q9L9I0|ZRAP_SALTY | B750: done | E750: ZRAP | F750: 151 | G750: 100 | H750: BacMet | I750: Metals | J750: Zinc resistance | K750: Zinc resistance regulator | L750: ZRAP | N750: Needs new annotations | P750: 3385 | Q750: No | R750: Yes
A751: gb|BA000007.3|+|4990267-4994296|ARO:3003288|Ecol_rpoB_RIF | B751: done | D751: InheritedSNPconfirmation | E751: RPOB | F751: 4029 | G751: 90.94 | H751: CARD | I751: Drugs | J751: Rifampin | K751: Rifampin-resistant beta-subunit of RNA polymerase RpoB | L751: RPOB | M751: RequiresSNPConfirmation | N751: Inherited annotations | P751: 43 | Q751: Yes | R751: No
A752: gb|NG_067968.1|+|100-655|ARO:3007770|aac(6')-Ib-cr10 | B752: done | E752: AAC6-PRIME | F752: 555 | G752: 99.1 | H752: CARD | I752: Drugs | J752: Aminoglycosides | K752: Aminoglycoside N-acetyltransferase | L752: AAC6-PRIME | N752: Mismatch in cluster | O752: Drugs|Aminoglycosides|Aminoglycoside_N-acetyltransferases|AAC6-PRIME ; Drugs|betalactams|Class_D_betalactamases|OXA | P752: 191 | Q752: Yes | R752: No
A753: gb|NG_067969.1|+|100-655|ARO:3007771|aac(6')-Ib-cr11 | B753: done | E753: AAC6-PRIME | F753: 555 | G753: 99.1 | H753: CARD | I753: Drugs | J753: Aminoglycosides | K753: Aminoglycoside N-acetyltransferase | L753: AAC6-PRIME | N753: Mismatch in cluster | O753: Drugs|Aminoglycosides|Aminoglycoside_N-acetyltransferases|AAC6-PRIME ; Drugs|betalactams|Class_D_betalactamases|OXA | P753: 191 | Q753: Yes | R753: No
A754: gb|AF043100.1|+|1-775|ARO:3001411|OXA-16 | B754: done | E754: OXA | F754: 774 | G754: 99.35 | H754: CARD | I754: Drugs | J754: betalactams | K754: Class D betalactamases | L754: OXA | N754: Mismatch in cluster | O754: Drugs|Aminoglycosides|Aminoglycoside_N-acetyltransferases|AAC6-PRIME ; Drugs|betalactams|Class_D_betalactamases|OXA | P754: 191 | Q754: Yes | R754: No
A755: gb|LC664104.1|+|0-801|ARO:3008472|OXA-1053 | B755: done | E755: OXA | F755: 801 | G755: 96.25 | H755: CARD | I755: Drugs | J755: betalactams | K755: Class D betalactamases | L755: OXA | N755: Mismatch in cluster | O755: Drugs|Aminoglycosides|Aminoglycoside_N-acetyltransferases|AAC6-PRIME ; Drugs|betalactams|Class_D_betalactamases|OXA | P755: 191 | Q755: Yes | R755: No
A756: gb|ON651492.1|+|0-801|ARO:3008505|OXA-1087 | B756: done | E756: OXA | F756: 801 | G756: 96.25 | H756: CARD | I756: Drugs | J756: betalactams | K756: Class D betalactamases | L756: OXA | N756: Mismatch in cluster | O756: Drugs|Aminoglycosides|Aminoglycoside_N-acetyltransferases|AAC6-PRIME ; Drugs|betalactams|Class_D_betalactamases|OXA | P756: 191 | Q756: Yes | R756: No
A757: gb|OR025344.1|+|0-801|ARO:3008616|OXA-1204 | B757: done | E757: OXA | F757: 801 | G757: 96.25 | H757: CARD | I757: Drugs | J757: betalactams | K757: Class D betalactamases | L757: OXA | N757: Mismatch in cluster | O757: Drugs|Aminoglycosides|Aminoglycoside_N-acetyltransferases|AAC6-PRIME ; Drugs|betalactams|Class_D_betalactamases|OXA | P757: 191 | Q757: Yes | R757: No
A758: gb|PP766715.1|+|0-801|ARO:3008657|OXA-1247 | B758: done | E758: OXA | F758: 801 | G758: 96.25 | H758: CARD | I758: Drugs | J758: betalactams | K758: Class D betalactamases | L758: OXA | N758: Mismatch in cluster | O758: Drugs|Aminoglycosides|Aminoglycoside_N-acetyltransferases|AAC6-PRIME ; Drugs|betalactams|Class_D_betalactamases|OXA | P758: 191 | Q758: Yes | R758: No
A759: gb|OQ948126.1|+|0-801|ARO:3008614|OXA-1202 | B759: done | E759: OXA | F759: 801 | G759: 96.38 | H759: CARD | I759: Drugs | J759: betalactams | K759: Class D betalactamases | L759: OXA | N759: Mismatch in cluster | O759: Drugs|Aminoglycosides|Aminoglycoside_N-acetyltransferases|AAC6-PRIME ; Drugs|betalactams|Class_D_betalactamases|OXA | P759: 191 | Q759: Yes | R759: No
A760: gb|PP328943.1|+|0-801|ARO:3008642|OXA-1232 | B760: done | E760: OXA | F760: 801 | G760: 96.38 | H760: CARD | I760: Drugs | J760: betalactams | K760: Class D betalactamases | L760: OXA | N760: Mismatch in cluster | O760: Drugs|Aminoglycosides|Aminoglycoside_N-acetyltransferases|AAC6-PRIME ; Drugs|betalactams|Class_D_betalactamases|OXA | P760: 191 | Q760: Yes | R760: No
A761: gb|MZ449318.1|+|0-801|ARO:3008436|OXA-1015 | B761: done | E761: OXA | F761: 801 | G761: 96.5 | H761: CARD | I761: Drugs | J761: betalactams | K761: Class D betalactamases | L761: OXA | N761: Mismatch in cluster | O761: Drugs|Aminoglycosides|Aminoglycoside_N-acetyltransferases|AAC6-PRIME ; Drugs|betalactams|Class_D_betalactamases|OXA | P761: 191 | Q761: Yes | R761: No
A762: gb|ON721379.1|+|0-801|ARO:3008538|OXA-1120 | B762: done | E762: OXA | F762: 801 | G762: 96.5 | H762: CARD | I762: Drugs | J762: betalactams | K762: Class D betalactamases | L762: OXA | N762: Mismatch in cluster | O762: Drugs|Aminoglycosides|Aminoglycoside_N-acetyltransferases|AAC6-PRIME ; Drugs|betalactams|Class_D_betalactamases|OXA | P762: 191 | Q762: Yes | R762: No
A763: gb|OP806897.1|+|0-801|ARO:3008588|OXA-1170 | B763: done | E763: OXA | F763: 801 | G763: 96.5 | H763: CARD | I763: Drugs | J763: betalactams | K763: Class D betalactamases | L763: OXA | N763: Mismatch in cluster | O763: Drugs|Aminoglycosides|Aminoglycoside_N-acetyltransferases|AAC6-PRIME ; Drugs|betalactams|Class_D_betalactamases|OXA | P763: 191 | Q763: Yes | R763: No
... A779: gb|OP806895.1|+|0-813|ARO:3008586|OXA-1168 | B779: done | E779: OXA | F779: 813 | G779: 95.2 | H779: CARD | I779: Drugs | J779: betalactams | K779: Class D betalactamases | L779: OXA | N779: Mismatch in cluster | O779: Drugs|Aminoglycosides|Aminoglycoside_N-acetyltransferases|AAC6-PRIME ; Drugs|betalactams|Class_D_betalactamases|OXA | P779: 191 | Q779: Yes | R779: No
A780: gb|NZ_JARETA010000011.1|+|134188-136825|ARO:3007751|Sisa_gyrA_FLO | B780: done | D780: InheritedSNPconfirmation | E780: GYRA | F780: 2637 | G780: 88.51 | H780: CARD | I780: Drugs | J780: Fluoroquinolones | K780: Fluoroquinolone-resistant DNA topoisomerases | L780: GYRA | M780: RequiresSNPConfirmation | N780: Inherited annotations | P780: 207 | Q780: Yes | R780: No
A781: gb|NZ_JARETA010000016.1|+|58093-60508|ARO:3007752|Sisa_gyrB_FLO | B781: done | E781: GYRB | F781: 2415 | G781: 88.9 | H781: CARD | I781: Drugs | J781: Fluoroquinolones | K781: Fluoroquinolone-resistant DNA topoisomerases | L781: GYRB | N781: Mismatch in cluster | O781: Drugs|Fluoroquinolones|Fluoroquinolone-resistant_DNA_topoisomerases|GYRB ; Drugs|Aminocoumarins|Aminocoumarin-resistant_DNA_topoisomerases|GYRBA | P781: 273 | Q781: Yes | R781: No
A782: gb|MT990446.1|+|54-1044|ARO:3007837|CARB-58 | B782: done | E782: CARB | F782: 990 | G782: 84.75 | H782: CARD | I782: Drugs | J782: betalactams | K782: Class A betalactamases | L782: CARB | N782: Mismatch in cluster | O782: Drugs|Aminoglycosides|Aminoglycoside_O-nucleotidyltransferases|ANT2-DPRIME ; Drugs|betalactams|Class_A_betalactamases|CARB ; Drugs|betalactams|Class_A_betalactamases|PSE | P782: 421 | Q782: Yes | R782: No
A783: gb|MH598530.1|+|0-1698|ARO:3007227|MCR-8.3 | B783: done | E783: MCR | F783: 1698 | G783: 95.35 | H783: CARD | I783: Drugs | J783: Lipopeptides | K783: Colistin phosphoethanolamine transferase | L783: MCR | N783: Inherited annotations | P783: 490 | Q783: Yes | R783: No
A784: gb|MH791448.1|+|0-1698|ARO:3007228|MCR-8.4 | B784: done | E784: MCR | F784: 1698 | G784: 95.35 | H784: CARD | I784: Drugs | J784: Lipopeptides | K784: Colistin phosphoethanolamine transferase | L784: MCR | N784: Inherited annotations | P784: 490 | Q784: Yes | R784: No
A785: gb|MK965519.1|-|5046-6690|ARO:3007281|MCR-5.4 | B785: done | E785: MCR | F785: 1644 | G785: 99.88 | H785: CARD | I785: Drugs | J785: Lipopeptides | K785: Colistin phosphoethanolamine transferase | L785: MCR | N785: Inherited annotations | P785: 522 | Q785: Yes | R785: No
A786: gb|MN873697.1|+|0-1626|ARO:3007234|MCR-1.23 | B786: done | E786: MCR | F786: 1626 | G786: 99.2 | H786: CARD | I786: Drugs | J786: Lipopeptides | K786: Colistin phosphoethanolamine transferase | L786: MCR | N786: Inherited annotations | P786: 531 | Q786: Yes | R786: No
A787: gb|MN879257.1|+|0-1626|ARO:3007243|MCR-1.24 | B787: done | E787: MCR | F787: 1626 | G787: 99.2 | H787: CARD | I787: Drugs | J787: Lipopeptides | K787: Colistin phosphoethanolamine transferase | L787: MCR | N787: Inherited annotations | P787: 531 | Q787: Yes | R787: No
A788: gb|MN879259.1|+|0-1626|ARO:3007247|MCR-1.25 | B788: done | E788: MCR | F788: 1626 | G788: 99.88 | H788: CARD | I788: Drugs | J788: Lipopeptides | K788: Colistin phosphoethanolamine transferase | L788: MCR | N788: Inherited annotations | P788: 531 | Q788: Yes | R788: No
A789: gb|MF084991.1|+|0-1626|ARO:3007289|MCR-1.32 | B789: done | E789: MCR | F789: 1626 | G789: 99.88 | H789: CARD | I789: Drugs | J789: Lipopeptides | K789: Colistin phosphoethanolamine transferase | L789: MCR | N789: Inherited annotations | P789: 531 | Q789: Yes | R789: No
A790: gb|MZ450868.1|+|0-1626|ARO:3007230|MCR-1.34 | B790: done | E790: MCR | F790: 1626 | G790: 99.94 | H790: CARD | I790: Drugs | J790: Lipopeptides | K790: Colistin phosphoethanolamine transferase | L790: MCR | N790: Inherited annotations | P790: 531 | Q790: Yes | R790: No
A791: gb|MT770924.1|+|0-1626|ARO:3007236|MCR-1.28 | B791: done | E791: MCR | F791: 1626 | G791: 99.94 | H791: CARD | I791: Drugs | J791: Lipopeptides | K791: Colistin phosphoethanolamine transferase | L791: MCR | N791: Inherited annotations | P791: 531 | Q791: Yes | R791: No
...

Sheet draft_annotations_20260818
A1: Gene_Accession | B1: ED_confirmation | C1: Notes | D1: ED_SNP | E1: Length | F1: Similarity | G1: Source_Database | H1: Type | I1: Class | J1: Mechanism | K1: Group | L1: SNP | M1: Annotation_Status | N1: Mismatch_Groups | O1: Cluster_ID | P1: Inheritted_matches? | Q1: New_Group
A2: gb|BA000007.3|+|4990267-4994296|ARO:3003288|Ecol_rpoB_RIF | B2: done | D2: InheritedSNPconfirmation | E2: 4029 | F2: 90.94 | G2: CARD | H2: Drugs | I2: Rifampin | J2: Rifampin-resistant beta-subunit of RNA polymerase RpoB | K2: RPOB | L2: RequiresSNPConfirmation | M2: Inherited annotations | O2: 43 | P2: Yes | Q2: No
A3: gb|NG_067968.1|+|100-655|ARO:3007770|aac(6')-Ib-cr10 | B3: done | E3: 555 | F3: 99.1 | G3: CARD | H3: Drugs | I3: Aminoglycosides | J3: Aminoglycoside N-acetyltransferases | K3: AAC6-PRIME | M3: Mismatch in cluster | N3: Drugs|Aminoglycosides|Aminoglycoside_N-acetyltransferases|AAC6-PRIME ; Drugs|betalactams|Class_D_betalactamases|OXA | O3: 191 | P3: Yes | Q3: No
A4: gb|NG_067969.1|+|100-655|ARO:3007771|aac(6')-Ib-cr11 | B4: done | E4: 555 | F4: 99.1 | G4: CARD | H4: Drugs | I4: Aminoglycosides | J4: Aminoglycoside N-acetyltransferases | K4: AAC6-PRIME | M4: Mismatch in cluster | N4: Drugs|Aminoglycosides|Aminoglycoside_N-acetyltransferases|AAC6-PRIME ; Drugs|betalactams|Class_D_betalactamases|OXA | O4: 191 | P4: Yes | Q4: No
A5: gb|AF043100.1|+|1-775|ARO:3001411|OXA-16 | B5: done | E5: 774 | F5: 99.35 | G5: CARD | H5: Drugs | I5: betalactams | J5: Class D betalactamases | K5: OXA | M5: Mismatch in cluster | N5: Drugs|Aminoglycosides|Aminoglycoside_N-acetyltransferases|AAC6-PRIME ; Drugs|betalactams|Class_D_betalactamases|OXA | O5: 191 | P5: Yes | Q5: No
A6: gb|LC664104.1|+|0-801|ARO:3008472|OXA-1053 | B6: done | E6: 801 | F6: 96.25 | G6: CARD | H6: Drugs | I6: betalactams | J6: Class D betalactamases | K6: OXA | M6: Mismatch in cluster | N6: Drugs|Aminoglycosides|Aminoglycoside_N-acetyltransferases|AAC6-PRIME ; Drugs|betalactams|Class_D_betalactamases|OXA | O6: 191 | P6: Yes | Q6: No
A7: gb|ON651492.1|+|0-801|ARO:3008505|OXA-1087 | B7: done | E7: 801 | F7: 96.25 | G7: CARD | H7: Drugs | I7: betalactams | J7: Class D betalactamases | K7: OXA | M7: Mismatch in cluster | N7: Drugs|Aminoglycosides|Aminoglycoside_N-acetyltransferases|AAC6-PRIME ; Drugs|betalactams|Class_D_betalactamases|OXA | O7: 191 | P7: Yes | Q7: No
A8: gb|OR025344.1|+|0-801|ARO:3008616|OXA-1204 | B8: done | E8: 801 | F8: 96.25 | G8: CARD | H8: Drugs | I8: betalactams | J8: Class D betalactamases | K8: OXA | M8: Mismatch in cluster | N8: Drugs|Aminoglycosides|Aminoglycoside_N-acetyltransferases|AAC6-PRIME ; Drugs|betalactams|Class_D_betalactamases|OXA | O8: 191 | P8: Yes | Q8: No
A9: gb|PP766715.1|+|0-801|ARO:3008657|OXA-1247 | B9: done | E9: 801 | F9: 96.25 | G9: CARD | H9: Drugs | I9: betalactams | J9: Class D betalactamases | K9: OXA | M9: Mismatch in cluster | N9: Drugs|Aminoglycosides|Aminoglycoside_N-acetyltransferases|AAC6-PRIME ; Drugs|betalactams|Class_D_betalactamases|OXA | O9: 191 | P9: Yes | Q9: No
A10: gb|OQ948126.1|+|0-801|ARO:3008614|OXA-1202 | B10: done | E10: 801 | F10: 96.38 | G10: CARD | H10: Drugs | I10: betalactams | J10: Class D betalactamases | K10: OXA | M10: Mismatch in cluster | N10: Drugs|Aminoglycosides|Aminoglycoside_N-acetyltransferases|AAC6-PRIME ; Drugs|betalactams|Class_D_betalactamases|OXA | O10: 191 | P10: Yes | Q10: No
A11: gb|PP328943.1|+|0-801|ARO:3008642|OXA-1232 | B11: done | E11: 801 | F11: 96.38 | G11: CARD | H11: Drugs | I11: betalactams | J11: Class D betalactamases | K11: OXA | M11: Mismatch in cluster | N11: Drugs|Aminoglycosides|Aminoglycoside_N-acetyltransferases|AAC6-PRIME ; Drugs|betalactams|Class_D_betalactamases|OXA | O11: 191 | P11: Yes | Q11: No
A12: gb|MZ449318.1|+|0-801|ARO:3008436|OXA-1015 | B12: done | E12: 801 | F12: 96.5 | G12: CARD | H12: Drugs | I12: betalactams | J12: Class D betalactamases | K12: OXA | M12: Mismatch in cluster | N12: Drugs|Aminoglycosides|Aminoglycoside_N-acetyltransferases|AAC6-PRIME ; Drugs|betalactams|Class_D_betalactamases|OXA | O12: 191 | P12: Yes | Q12: No
A13: gb|ON721379.1|+|0-801|ARO:3008538|OXA-1120 | B13: done | E13: 801 | F13: 96.5 | G13: CARD | H13: Drugs | I13: betalactams | J13: Class D betalactamases | K13: OXA | M13: Mismatch in cluster | N13: Drugs|Aminoglycosides|Aminoglycoside_N-acetyltransferases|AAC6-PRIME ; Drugs|betalactams|Class_D_betalactamases|OXA | O13: 191 | P13: Yes | Q13: No
A14: gb|OP806897.1|+|0-801|ARO:3008588|OXA-1170 | B14: done | E14: 801 | F14: 96.5 | G14: CARD | H14: Drugs | I14: betalactams | J14: Class D betalactamases | K14: OXA | M14: Mismatch in cluster | N14: Drugs|Aminoglycosides|Aminoglycoside_N-acetyltransferases|AAC6-PRIME ; Drugs|betalactams|Class_D_betalactamases|OXA | O14: 191 | P14: Yes | Q14: No
... A30: gb|OP806895.1|+|0-813|ARO:3008586|OXA-1168 | B30: done | E30: 813 | F30: 95.2 | G30: CARD | H30: Drugs | I30: betalactams | J30: Class D betalactamases | K30: OXA | M30: Mismatch in cluster | N30: Drugs|Aminoglycosides|Aminoglycoside_N-acetyltransferases|AAC6-PRIME ; Drugs|betalactams|Class_D_betalactamases|OXA | O30: 191 | P30: Yes | Q30: No
A31: gb|NZ_JARETA010000011.1|+|134188-136825|ARO:3007751|Sisa_gyrA_FLO | B31: done | D31: InheritedSNPconfirmation | E31: 2637 | F31: 88.51 | G31: CARD | H31: Drugs | I31: Fluoroquinolones | J31: Fluoroquinolone-resistant DNA topoisomerases | K31: GYRA | L31: RequiresSNPConfirmation | M31: Inherited annotations | O31: 207 | P31: Yes | Q31: No
A32: gb|NZ_JARETA010000016.1|+|58093-60508|ARO:3007752|Sisa_gyrB_FLO | B32: done | E32: 2415 | F32: 88.9 | G32: CARD | H32: Drugs | I32: Fluoroquinolones | J32: Fluoroquinolone-resistant DNA topoisomerases | K32: GYRB | L32: RequiresSNPConfirmation | M32: Mismatch in cluster | N32: Drugs|Fluoroquinolones|Fluoroquinolone-resistant_DNA_topoisomerases|GYRB ; Drugs|Aminocoumarins|Aminocoumarin-resistant_DNA_topoisomerases|GYRBA | O32: 273 | P32: Yes | Q32: No
A33: gb|MT990446.1|+|54-1044|ARO:3007837|CARB-58 | B33: done | E33: 990 | F33: 84.75 | G33: CARD | H33: Drugs | I33: betalactams | J33: Class A betalactamases | K33: CARB | M33: Mismatch in cluster | N33: Drugs|Aminoglycosides|Aminoglycoside_O-nucleotidyltransferases|ANT2-DPRIME ; Drugs|betalactams|Class_A_betalactamases|CARB ; Drugs|betalactams|Class_A_betalactamases|PSE | O33: 421 | P33: Yes | Q33: No
A34: gb|MH598530.1|+|0-1698|ARO:3007227|MCR-8.3 | B34: done | E34: 1698 | F34: 95.35 | G34: CARD | H34: Drugs | I34: Lipopeptides | J34: Colistin phosphoethanolamine transferase | K34: MCR | M34: Inherited annotations | O34: 490 | P34: Yes | Q34: No
A35: gb|MH791448.1|+|0-1698|ARO:3007228|MCR-8.4 | B35: done | E35: 1698 | F35: 95.35 | G35: CARD | H35: Drugs | I35: Lipopeptides | J35: Colistin phosphoethanolamine transferase | K35: MCR | M35: Inherited annotations | O35: 490 | P35: Yes | Q35: No
A36: gb|MK965519.1|-|5046-6690|ARO:3007281|MCR-5.4 | B36: done | E36: 1644 | F36: 99.88 | G36: CARD | H36: Drugs | I36: Lipopeptides | J36: Colistin phosphoethanolamine transferase | K36: MCR | M36: Inherited annotations | O36: 522 | P36: Yes | Q36: No
A37: gb|MN873697.1|+|0-1626|ARO:3007234|MCR-1.23 | B37: done | E37: 1626 | F37: 99.2 | G37: CARD | H37: Drugs | I37: Lipopeptides | J37: Colistin phosphoethanolamine transferase | K37: MCR | M37: Inherited annotations | O37: 531 | P37: Yes | Q37: No
A38: gb|MN879257.1|+|0-1626|ARO:3007243|MCR-1.24 | B38: done | E38: 1626 | F38: 99.2 | G38: CARD | H38: Drugs | I38: Lipopeptides | J38: Colistin phosphoethanolamine transferase | K38: MCR | M38: Inherited annotations | O38: 531 | P38: Yes | Q38: No
A39: gb|MN879259.1|+|0-1626|ARO:3007247|MCR-1.25 | B39: done | E39: 1626 | F39: 99.88 | G39: CARD | H39: Drugs | I39: Lipopeptides | J39: Colistin phosphoethanolamine transferase | K39: MCR | M39: Inherited annotations | O39: 531 | P39: Yes | Q39: No
A40: gb|MF084991.1|+|0-1626|ARO:3007289|MCR-1.32 | B40: done | E40: 1626 | F40: 99.88 | G40: CARD | H40: Drugs | I40: Lipopeptides | J40: Colistin phosphoethanolamine transferase | K40: MCR | M40: Inherited annotations | O40: 531 | P40: Yes | Q40: No
A41: gb|MZ450868.1|+|0-1626|ARO:3007230|MCR-1.34 | B41: done | E41: 1626 | F41: 99.94 | G41: CARD | H41: Drugs | I41: Lipopeptides | J41: Colistin phosphoethanolamine transferase | K41: MCR | M41: Inherited annotations | O41: 531 | P41: Yes | Q41: No
A42: gb|MT770924.1|+|0-1626|ARO:3007236|MCR-1.28 | B42: done | E42: 1626 | F42: 99.94 | G42: CARD | H42: Drugs | I42: Lipopeptides | J42: Colistin phosphoethanolamine transferase | K42: MCR | M42: Inherited annotations | O42: 531 | P42: Yes | Q42: No
A43: gb|MN017134.1|+|0-1626|ARO:3007239|MCR-1.22 | B43: done | E43: 1626 | F43: 99.94 | G43: CARD | H43: Drugs | I43: Lipopeptides | J43: Colistin phosphoethanolamine transferase | K43: MCR | M43: Inherited annotations | O43: 531 | P43: Yes | Q43: No
A44: gb|MT731964.1|+|0-1626|ARO:3007241|MCR-1.29 | B44: done | E44: 1626 | F44: 99.94 | G44: CARD | H44: Drugs | I44: Lipopeptides | J44: Colistin phosphoethanolamine transferase | K44: MCR | M44: Inherited annotations | O44: 531 | P44: Yes | Q44: No
A45: gb|MT731965.1|+|0-1626|ARO:3007242|MCR-1.30 | B45: done | E45: 1626 | F45: 99.94 | G45: CARD | H45: Drugs | I45: Lipopeptides | J45: Colistin phosphoethanolamine transferase | K45: MCR | M45: Inherited annotations | O45: 531 | P45: Yes | Q45: No
... A66: gb|MT757844.1|+|0-1617|ARO:3007288|MCR-2.6 | B66: done | E66: 1617 | F66: 96.35 | G66: CARD | H66: Drugs | I66: Lipopeptides | J66: Colistin phosphoethanolamine transferase | K66: MCR | M66: Inherited annotations | O66: 544 | P66: Yes | Q66: No
A67: gb|OP142444.1|+|0-1137|ARO:3008385|MOX-17 | B67: done | E67: 1137 | F67: 90.33 | G67: CARD | H67: Drugs | I67: betalactams | J67: Class C betalactamases | K67: MOX | M67: Mismatch in cluster | N67: Drugs|betalactams|Class_C_betalactamases|AQU ; Drugs|betalactams|Class_C_betalactamases|CEPH ; Drugs|betalactams|Class_C_betalactamases|CMY ; Drugs|betalactams|Class_C_betalactamases|MOX | O67: 568 | P67: Yes | Q67: No
A68: gb|LC732556.1|+|0-1149|ARO:3008389|MOX-21 | B68: done | E68: 1149 | F68: 90.51 | G68: CARD | H68: Drugs | I68: betalactams | J68: Class C betalactamases | K68: MOX | M68: Mismatch in cluster | N68: Drugs|betalactams|Class_C_betalactamases|AQU ; Drugs|betalactams|Class_C_betalactamases|CEPH ; Drugs|betalactams|Class_C_betalactamases|CMY ; Drugs|betalactams|Class_C_betalactamases|MOX | O68: 568 | P68: Yes | Q68: No
A69: gb|LC733693.1|+|0-1149|ARO:3008391|MOX-23 | B69: done | E69: 1149 | F69: 92.52 | G69: CARD | H69: Drugs | I69: betalactams | J69: Class C betalactamases | K69: MOX | M69: Mismatch in cluster | N69: Drugs|betalactams|Class_C_betalactamases|AQU ; Drugs|betalactams|Class_C_betalactamases|CEPH ; Drugs|betalactams|Class_C_betalactamases|CMY ; Drugs|betalactams|Class_C_betalactamases|MOX | O69: 568 | P69: Yes | Q69: No
A70: gb|LC733692.1|+|0-1149|ARO:3008390|MOX-22 | B70: done | E70: 1149 | F70: 92.86 | G70: CARD | H70: Drugs | I70: betalactams | J70: Class C betalactamases | K70: MOX | M70: Mismatch in cluster | N70: Drugs|betalactams|Class_C_betalactamases|AQU ; Drugs|betalactams|Class_C_betalactamases|CEPH ; Drugs|betalactams|Class_C_betalactamases|CMY ; Drugs|betalactams|Class_C_betalactamases|MOX | O70: 568 | P70: Yes | Q70: No
A71: gb|LC732553.1|+|0-1149|ARO:3008386|MOX-18 | B71: done | E71: 1149 | F71: 93.04 | G71: CARD | H71: Drugs | I71: betalactams | J71: Class C betalactamases | K71: MOX | M71: Mismatch in cluster | N71: Drugs|betalactams|Class_C_betalactamases|AQU ; Drugs|betalactams|Class_C_betalactamases|CEPH ; Drugs|betalactams|Class_C_betalactamases|CMY ; Drugs|betalactams|Class_C_betalactamases|MOX | O71: 568 | P71: Yes | Q71: No
A72: gb|LC732555.1|+|0-1149|ARO:3008388|MOX-20 | B72: done | E72: 1149 | F72: 93.12 | G72: CARD | H72: Drugs | I72: betalactams | J72: Class C betalactamases | K72: MOX | M72: Mismatch in cluster | N72: Drugs|betalactams|Class_C_betalactamases|AQU ; Drugs|betalactams|Class_C_betalactamases|CEPH ; Drugs|betalactams|Class_C_betalactamases|CMY ; Drugs|betalactams|Class_C_betalactamases|MOX | O72: 568 | P72: Yes | Q72: No
A73: gb|LC659430.1|+|0-1149|ARO:3008384|MOX-16 | B73: done | E73: 1149 | F73: 97.65 | G73: CARD | H73: Drugs | I73: betalactams | J73: Class C betalactamases | K73: MOX | M73: Mismatch in cluster | N73: Drugs|betalactams|Class_C_betalactamases|AQU ; Drugs|betalactams|Class_C_betalactamases|CEPH ; Drugs|betalactams|Class_C_betalactamases|CMY ; Drugs|betalactams|Class_C_betalactamases|MOX | O73: 568 | P73: Yes | Q73: No
A74: gb|MZ133817.1|+|0-1152|ARO:3008383|MOX-15 | B74: done | E74: 1152 | F74: 85.5 | G74: CARD | H74: Drugs | I74: betalactams | J74: Class C betalactamases | K74: MOX | M74: Mismatch in cluster | N74: Drugs|betalactams|Class_C_betalactamases|AQU ; Drugs|betalactams|Class_C_betalactamases|CEPH ; Drugs|betalactams|Class_C_betalactamases|CMY ; Drugs|betalactams|Class_C_betalactamases|MOX | O74: 568 | P74: Yes | Q74: No
A75: gb|LC732554.1|+|0-1152|ARO:3008387|MOX-19 | B75: done | E75: 1152 | F75: 85.5 | G75: CARD | H75: Drugs | I75: betalactams | J75: Class C betalactamases | K75: MOX | M75: Mismatch in cluster | N75: Drugs|betalactams|Class_C_betalactamases|AQU ; Drugs|betalactams|Class_C_betalactamases|CEPH ; Drugs|betalactams|Class_C_betalactamases|CMY ; Drugs|betalactams|Class_C_betalactamases|MOX | O75: 568 | P75: Yes | Q75: No
...

Sheet v4_pivot
A1: New_Group | B1: (Multiple Items)
A2: Annotation_Status | B2: (Multiple Items)
A4: Row Labels
A5: AADT | B5: =VLOOKUP(A5,meg_v3!E:E,1,FALSE) -> #N/A
A6: AGRA | B6: =VLOOKUP(A6,meg_v3!E:E,1,FALSE) -> #N/A
A7: AHM | B7: =VLOOKUP(A7,meg_v3!E:E,1,FALSE) -> #N/A
A8: AKO | B8: =VLOOKUP(A8,meg_v3!E:E,1,FALSE) -> #N/A
A9: ALD | B9: =VLOOKUP(A9,meg_v3!E:E,1,FALSE) -> #N/A
A10: ALME | B10: =VLOOKUP(A10,meg_v3!E:E,1,FALSE) -> #N/A
A11: ALMF | B11: =VLOOKUP(A11,meg_v3!E:E,1,FALSE) -> #N/A
A12: AMPR | B12: =VLOOKUP(A12,meg_v3!E:E,1,FALSE) -> #N/A
A13: AMZ | B13: =VLOOKUP(A13,meg_v3!E:E,1,FALSE) -> #N/A
A14: ARSN1 | B14: =VLOOKUP(A14,meg_v3!E:E,1,FALSE) -> #N/A
A15: ARSN2 | B15: =VLOOKUP(A15,meg_v3!E:E,1,FALSE) -> #N/A
A16: ASDC | B16: =VLOOKUP(A16,meg_v3!E:E,1,FALSE) -> #N/A
... A191: Grand Total | B191: =VLOOKUP(A191,meg_v3!E:E,1,FALSE) -> #N/A

Sheet new_annotations_to_collapse
A1: 23S rRNA methyltransferase | B1: New
A2: ABC transporter ATP-binding protein | B2: New
A3: ABC-F ATPase ribosomal protection protein | B3: New
A4: ABC-F ribosomal protection protein | B4: New
A5: Aminoglycoside phosphotransferase | B5: New
A6: Arsenic resistance N-acetyltransferases | B6: New
A7: Arsinothricin resistance N-acetyltransferases | B7: New
A8: Cadmium resistance chaperone | B8: New
A9: Chloramphenicol efflux transporter | B9: New
A10: Chloramphenicol O-acetyltransferase | B10: New
A11: Cycloserine-resistant mutation | B11: New
A12: Cytoplasmic membrane protein | B12: New
... A72: Fluoroquinolones efflux pump mutation | B72: New

Sheet meg_v3
A1: header | B1: type | C1: class | D1: mechanism | E1: group | F1: snp
A2: MEG_1|Drugs|Aminoglycosides|Aminoglycoside-resistant_16S_ribosomal_subunit_protein|A16S|RequiresSNPConfirmation | B2: Drugs | C2: Aminoglycosides | D2: Aminoglycoside-resistant 16S ribosomal subunit protein | E2: A16S | F2: RequiresSNPConfirmation
A3: MEG_2|Drugs|Aminoglycosides|Aminoglycoside-resistant_16S_ribosomal_subunit_protein|A16S|RequiresSNPConfirmation | B3: Drugs | C3: Aminoglycosides | D3: Aminoglycoside-resistant 16S ribosomal subunit protein | E3: A16S | F3: RequiresSNPConfirmation
A4: MEG_3|Drugs|Aminoglycosides|Aminoglycoside-resistant_16S_ribosomal_subunit_protein|A16S|RequiresSNPConfirmation | B4: Drugs | C4: Aminoglycosides | D4: Aminoglycoside-resistant 16S ribosomal subunit protein | E4: A16S | F4: RequiresSNPConfirmation
A5: MEG_4|Drugs|Aminoglycosides|Aminoglycoside-resistant_16S_ribosomal_subunit_protein|A16S|RequiresSNPConfirmation | B5: Drugs | C5: Aminoglycosides | D5: Aminoglycoside-resistant 16S ribosomal subunit protein | E5: A16S | F5: RequiresSNPConfirmation
A6: MEG_5|Drugs|Aminoglycosides|Aminoglycoside-resistant_16S_ribosomal_subunit_protein|A16S|RequiresSNPConfirmation | B6: Drugs | C6: Aminoglycosides | D6: Aminoglycoside-resistant 16S ribosomal subunit protein | E6: A16S | F6: RequiresSNPConfirmation
A7: MEG_6|Drugs|Aminoglycosides|Aminoglycoside-resistant_16S_ribosomal_subunit_protein|A16S|RequiresSNPConfirmation | B7: Drugs | C7: Aminoglycosides | D7: Aminoglycoside-resistant 16S ribosomal subunit protein | E7: A16S | F7: RequiresSNPConfirmation
A8: MEG_7|Drugs|Aminoglycosides|Aminoglycoside-resistant_16S_ribosomal_subunit_protein|A16S|RequiresSNPConfirmation | B8: Drugs | C8: Aminoglycosides | D8: Aminoglycoside-resistant 16S ribosomal subunit protein | E8: A16S | F8: RequiresSNPConfirmation
A9: MEG_8|Drugs|Aminoglycosides|Aminoglycoside-resistant_16S_ribosomal_subunit_protein|A16S|RequiresSNPConfirmation | B9: Drugs | C9: Aminoglycosides | D9: Aminoglycoside-resistant 16S ribosomal subunit protein | E9: A16S | F9: RequiresSNPConfirmation
A10: MEG_9|Drugs|Aminoglycosides|Aminoglycoside-resistant_16S_ribosomal_subunit_protein|A16S|RequiresSNPConfirmation | B10: Drugs | C10: Aminoglycosides | D10: Aminoglycoside-resistant 16S ribosomal subunit protein | E10: A16S | F10: RequiresSNPConfirmation
A11: MEG_10|Drugs|Aminoglycosides|Aminoglycoside-resistant_16S_ribosomal_subunit_protein|A16S|RequiresSNPConfirmation | B11: Drugs | C11: Aminoglycosides | D11: Aminoglycoside-resistant 16S ribosomal subunit protein | E11: A16S | F11: RequiresSNPConfirmation
A12: MEG_11|Drugs|Aminoglycosides|Aminoglycoside-resistant_16S_ribosomal_subunit_protein|A16S|RequiresSNPConfirmation | B12: Drugs | C12: Aminoglycosides | D12: Aminoglycoside-resistant 16S ribosomal subunit protein | E12: A16S | F12: RequiresSNPConfirmation
A13: MEG_12|Drugs|Aminoglycosides|Aminoglycoside-resistant_16S_ribosomal_subunit_protein|A16S|RequiresSNPConfirmation | B13: Drugs | C13: Aminoglycosides | D13: Aminoglycoside-resistant 16S ribosomal subunit protein | E13: A16S | F13: RequiresSNPConfirmation
A14: MEG_13|Drugs|Aminoglycosides|Aminoglycoside_N-acetyltransferases|AAC2-PRIME | B14: Drugs | C14: Aminoglycosides | D14: Aminoglycoside N-acetyltransferases | E14: AAC2-PRIME
A15: MEG_14|Drugs|Aminoglycosides|Aminoglycoside_N-acetyltransferases|AAC2-PRIME | B15: Drugs | C15: Aminoglycosides | D15: Aminoglycoside N-acetyltransferases | E15: AAC2-PRIME
A16: MEG_15|Drugs|Aminoglycosides|Aminoglycoside_N-acetyltransferases|AAC2-PRIME | B16: Drugs | C16: Aminoglycosides | D16: Aminoglycoside N-acetyltransferases | E16: AAC2-PRIME
A17: MEG_16|Drugs|Aminoglycosides|Aminoglycoside_N-acetyltransferases|AAC2-PRIME | B17: Drugs | C17: Aminoglycosides | D17: Aminoglycoside N-acetyltransferases | E17: AAC2-PRIME
A18: MEG_17|Drugs|Aminoglycosides|Aminoglycoside_N-acetyltransferases|AAC2-PRIME | B18: Drugs | C18: Aminoglycosides | D18: Aminoglycoside N-acetyltransferases | E18: AAC2-PRIME
A19: MEG_18|Drugs|Aminoglycosides|Aminoglycoside_N-acetyltransferases|AAC2-PRIME | B19: Drugs | C19: Aminoglycosides | D19: Aminoglycoside N-acetyltransferases | E19: AAC2-PRIME
A20: MEG_19|Drugs|Aminoglycosides|Aminoglycoside_N-acetyltransferases|AAC2-PRIME | B20: Drugs | C20: Aminoglycosides | D20: Aminoglycoside N-acetyltransferases | E20: AAC2-PRIME
A21: MEG_20|Drugs|Aminoglycosides|Aminoglycoside_N-acetyltransferases|AAC3 | B21: Drugs | C21: Aminoglycosides | D21: Aminoglycoside N-acetyltransferases | E21: AAC3
A22: MEG_21|Drugs|Aminoglycosides|Aminoglycoside_N-acetyltransferases|AAC3 | B22: Drugs | C22: Aminoglycosides | D22: Aminoglycoside N-acetyltransferases | E22: AAC3
A23: MEG_22|Drugs|Aminoglycosides|Aminoglycoside_N-acetyltransferases|AAC3 | B23: Drugs | C23: Aminoglycosides | D23: Aminoglycoside N-acetyltransferases | E23: AAC3
A24: MEG_23|Drugs|Aminoglycosides|Aminoglycoside_N-acetyltransferases|AAC3 | B24: Drugs | C24: Aminoglycosides | D24: Aminoglycoside N-acetyltransferases | E24: AAC3
A25: MEG_24|Drugs|Aminoglycosides|Aminoglycoside_N-acetyltransferases|AAC3 | B25: Drugs | C25: Aminoglycosides | D25: Aminoglycoside N-acetyltransferases | E25: AAC3
... A410: MEG_410|Multi-compound|Drug_and_biocide_resistance|Drug_and_biocide_RND_efflux_pumps|ACRF | B410: Multi-compound | C410: Drug and biocide resistance | D410: Drug and biocide RND efflux pumps | E410: ACRF
A411: MEG_411|Multi-compound|Drug_and_biocide_resistance|Drug_and_biocide_RND_efflux_regulator|ACRR|RequiresSNPConfirmation | B411: Multi-compound | C411: Drug and biocide resistance | D411: Drug and biocide RND efflux regulator | E411: ACRR | F411: RequiresSNPConfirmation
A412: MEG_412|Multi-compound|Drug_and_biocide_resistance|Drug_and_biocide_RND_efflux_regulator|ACRR|RequiresSNPConfirmation | B412: Multi-compound | C412: Drug and biocide resistance | D412: Drug and biocide RND efflux regulator | E412: ACRR | F412: RequiresSNPConfirmation
A413: MEG_413|Multi-compound|Drug_and_biocide_resistance|Drug_and_biocide_RND_efflux_regulator|ACRR|RequiresSNPConfirmation | B413: Multi-compound | C413: Drug and biocide resistance | D413: Drug and biocide RND efflux regulator | E413: ACRR | F413: RequiresSNPConfirmation
A414: MEG_414|Multi-compound|Drug_and_biocide_resistance|Drug_and_biocide_RND_efflux_regulator|ACRR|RequiresSNPConfirmation | B414: Multi-compound | C414: Drug and biocide resistance | D414: Drug and biocide RND efflux regulator | E414: ACRR | F414: RequiresSNPConfirmation
A415: MEG_415|Multi-compound|Drug_and_biocide_resistance|Drug_and_biocide_RND_efflux_regulator|ACRS | B415: Multi-compound | C415: Drug and biocide resistance | D415: Drug and biocide RND efflux regulator | E415: ACRS
A416: MEG_416|Drugs|betalactams|Class_C_betalactamases|ACT | B416: Drugs | C416: betalactams | D416: Class C betalactamases | E416: ACT
A417: MEG_417|Drugs|betalactams|Class_C_betalactamases|ACT | B417: Drugs | C417: betalactams | D417: Class C betalactamases | E417: ACT
A418: MEG_418|Drugs|betalactams|Class_C_betalactamases|ACT | B418: Drugs | C418: betalactams | D418: Class C betalactamases | E418: ACT
A419: MEG_419|Drugs|betalactams|Class_C_betalactamases|ACT | B419: Drugs | C419: betalactams | D419: Class C betalactamases | E419: ACT
A420: MEG_420|Drugs|betalactams|Class_C_betalactamases|ACT | B420: Drugs | C420: betalactams | D420: Class C betalactamases | E420: ACT
A421: MEG_421|Drugs|betalactams|Class_C_betalactamases|ACT | B421: Drugs | C421: betalactams | D421: Class C betalactamases | E421: ACT
A422: MEG_422|Drugs|betalactams|Class_C_betalactamases|ACT | B422: Drugs | C422: betalactams | D422: Class C betalactamases | E422: ACT
A423: MEG_423|Drugs|betalactams|Class_C_betalactamases|ACT | B423: Drugs | C423: betalactams | D423: Class C betalactamases | E423: ACT
A424: MEG_424|Drugs|betalactams|Class_C_betalactamases|ACT | B424: Drugs | C424: betalactams | D424: Class C betalactamases | E424: ACT
...
